2023-04-29 15:17:10,345 INFO    StreamThr :3523920 [internal.py:wandb_internal():86] W&B internal server running at pid: 3523920, started at: 2023-04-29 15:17:10.345251
2023-04-29 15:17:10,348 DEBUG   HandlerThread:3523920 [handler.py:handle_request():144] handle_request: status
2023-04-29 15:17:10,353 INFO    WriterThread:3523920 [datastore.py:open_for_write():85] open: /DATATWO/users/mincut/Object-Centric-VideoAnswering/TemporalGNN/wandb/run-20230429_151710-lcdyfhoz/run-lcdyfhoz.wandb
2023-04-29 15:17:10,354 DEBUG   SenderThread:3523920 [sender.py:send():375] send: header
2023-04-29 15:17:10,355 DEBUG   SenderThread:3523920 [sender.py:send():375] send: run
2023-04-29 15:17:15,353 DEBUG   HandlerThread:3523920 [handler.py:handle_request():144] handle_request: keepalive
2023-04-29 15:17:16,620 DEBUG   HandlerThread:3523920 [handler.py:handle_request():144] handle_request: shutdown
2023-04-29 15:17:16,620 INFO    HandlerThread:3523920 [handler.py:finish():845] shutting down handler
2023-04-29 15:17:17,355 INFO    WriterThread:3523920 [datastore.py:close():298] close: /DATATWO/users/mincut/Object-Centric-VideoAnswering/TemporalGNN/wandb/run-20230429_151710-lcdyfhoz/run-lcdyfhoz.wandb
2023-04-29 15:17:43,843 INFO    SenderThread:3523920 [retry.py:__call__():172] Retry attempt failed:
Traceback (most recent call last):
  File "/home/mincut/miniconda3/envs/vidgnn/lib/python3.10/site-packages/urllib3/connection.py", line 174, in _new_conn
    conn = connection.create_connection(
  File "/home/mincut/miniconda3/envs/vidgnn/lib/python3.10/site-packages/urllib3/util/connection.py", line 95, in create_connection
    raise err
  File "/home/mincut/miniconda3/envs/vidgnn/lib/python3.10/site-packages/urllib3/util/connection.py", line 85, in create_connection
    sock.connect(sa)
TimeoutError: timed out

During handling of the above exception, another exception occurred:

Traceback (most recent call last):
  File "/home/mincut/miniconda3/envs/vidgnn/lib/python3.10/site-packages/urllib3/connectionpool.py", line 703, in urlopen
    httplib_response = self._make_request(
  File "/home/mincut/miniconda3/envs/vidgnn/lib/python3.10/site-packages/urllib3/connectionpool.py", line 386, in _make_request
    self._validate_conn(conn)
  File "/home/mincut/miniconda3/envs/vidgnn/lib/python3.10/site-packages/urllib3/connectionpool.py", line 1042, in _validate_conn
    conn.connect()
  File "/home/mincut/miniconda3/envs/vidgnn/lib/python3.10/site-packages/urllib3/connection.py", line 358, in connect
    self.sock = conn = self._new_conn()
  File "/home/mincut/miniconda3/envs/vidgnn/lib/python3.10/site-packages/urllib3/connection.py", line 179, in _new_conn
    raise ConnectTimeoutError(
urllib3.exceptions.ConnectTimeoutError: (<urllib3.connection.HTTPSConnection object at 0x7f1bb3705720>, 'Connection to api.wandb.ai timed out. (connect timeout=10)')

During handling of the above exception, another exception occurred:

Traceback (most recent call last):
  File "/home/mincut/miniconda3/envs/vidgnn/lib/python3.10/site-packages/requests/adapters.py", line 489, in send
    resp = conn.urlopen(
  File "/home/mincut/miniconda3/envs/vidgnn/lib/python3.10/site-packages/urllib3/connectionpool.py", line 787, in urlopen
    retries = retries.increment(
  File "/home/mincut/miniconda3/envs/vidgnn/lib/python3.10/site-packages/urllib3/util/retry.py", line 592, in increment
    raise MaxRetryError(_pool, url, error or ResponseError(cause))
urllib3.exceptions.MaxRetryError: HTTPSConnectionPool(host='api.wandb.ai', port=443): Max retries exceeded with url: /graphql (Caused by ConnectTimeoutError(<urllib3.connection.HTTPSConnection object at 0x7f1bb3705720>, 'Connection to api.wandb.ai timed out. (connect timeout=10)'))

During handling of the above exception, another exception occurred:

Traceback (most recent call last):
  File "/home/mincut/miniconda3/envs/vidgnn/lib/python3.10/site-packages/wandb/sdk/lib/retry.py", line 131, in __call__
    result = self._call_fn(*args, **kwargs)
  File "/home/mincut/miniconda3/envs/vidgnn/lib/python3.10/site-packages/wandb/sdk/internal/internal_api.py", line 285, in execute
    return self.client.execute(*args, **kwargs)  # type: ignore
  File "/home/mincut/miniconda3/envs/vidgnn/lib/python3.10/site-packages/wandb/vendor/gql-0.2.0/wandb_gql/client.py", line 52, in execute
    result = self._get_result(document, *args, **kwargs)
  File "/home/mincut/miniconda3/envs/vidgnn/lib/python3.10/site-packages/wandb/vendor/gql-0.2.0/wandb_gql/client.py", line 60, in _get_result
    return self.transport.execute(document, *args, **kwargs)
  File "/home/mincut/miniconda3/envs/vidgnn/lib/python3.10/site-packages/wandb/sdk/lib/gql_request.py", line 55, in execute
    request = self.session.post(self.url, **post_args)
  File "/home/mincut/miniconda3/envs/vidgnn/lib/python3.10/site-packages/requests/sessions.py", line 635, in post
    return self.request("POST", url, data=data, json=json, **kwargs)
  File "/home/mincut/miniconda3/envs/vidgnn/lib/python3.10/site-packages/requests/sessions.py", line 587, in request
    resp = self.send(prep, **send_kwargs)
  File "/home/mincut/miniconda3/envs/vidgnn/lib/python3.10/site-packages/requests/sessions.py", line 701, in send
    r = adapter.send(request, **kwargs)
  File "/home/mincut/miniconda3/envs/vidgnn/lib/python3.10/site-packages/requests/adapters.py", line 553, in send
    raise ConnectTimeout(e, request=request)
requests.exceptions.ConnectTimeout: HTTPSConnectionPool(host='api.wandb.ai', port=443): Max retries exceeded with url: /graphql (Caused by ConnectTimeoutError(<urllib3.connection.HTTPSConnection object at 0x7f1bb3705720>, 'Connection to api.wandb.ai timed out. (connect timeout=10)'))
2023-05-06 15:22:02,020 ERROR   SenderThread:3523920 [sender.py:send_run():979] HTTPSConnectionPool(host='api.wandb.ai', port=443): Max retries exceeded with url: /graphql (Caused by ConnectTimeoutError(<urllib3.connection.HTTPSConnection object at 0x7f1bb3705510>, 'Connection to api.wandb.ai timed out. (connect timeout=10)'))
Traceback (most recent call last):
  File "/home/mincut/miniconda3/envs/vidgnn/lib/python3.10/site-packages/urllib3/connection.py", line 174, in _new_conn
    conn = connection.create_connection(
  File "/home/mincut/miniconda3/envs/vidgnn/lib/python3.10/site-packages/urllib3/util/connection.py", line 95, in create_connection
    raise err
  File "/home/mincut/miniconda3/envs/vidgnn/lib/python3.10/site-packages/urllib3/util/connection.py", line 85, in create_connection
    sock.connect(sa)
TimeoutError: timed out

During handling of the above exception, another exception occurred:

Traceback (most recent call last):
  File "/home/mincut/miniconda3/envs/vidgnn/lib/python3.10/site-packages/urllib3/connectionpool.py", line 703, in urlopen
    httplib_response = self._make_request(
  File "/home/mincut/miniconda3/envs/vidgnn/lib/python3.10/site-packages/urllib3/connectionpool.py", line 386, in _make_request
    self._validate_conn(conn)
  File "/home/mincut/miniconda3/envs/vidgnn/lib/python3.10/site-packages/urllib3/connectionpool.py", line 1042, in _validate_conn
    conn.connect()
  File "/home/mincut/miniconda3/envs/vidgnn/lib/python3.10/site-packages/urllib3/connection.py", line 358, in connect
    self.sock = conn = self._new_conn()
  File "/home/mincut/miniconda3/envs/vidgnn/lib/python3.10/site-packages/urllib3/connection.py", line 179, in _new_conn
    raise ConnectTimeoutError(
urllib3.exceptions.ConnectTimeoutError: (<urllib3.connection.HTTPSConnection object at 0x7f1bb3705510>, 'Connection to api.wandb.ai timed out. (connect timeout=10)')

During handling of the above exception, another exception occurred:

Traceback (most recent call last):
  File "/home/mincut/miniconda3/envs/vidgnn/lib/python3.10/site-packages/requests/adapters.py", line 489, in send
    resp = conn.urlopen(
  File "/home/mincut/miniconda3/envs/vidgnn/lib/python3.10/site-packages/urllib3/connectionpool.py", line 787, in urlopen
    retries = retries.increment(
  File "/home/mincut/miniconda3/envs/vidgnn/lib/python3.10/site-packages/urllib3/util/retry.py", line 592, in increment
    raise MaxRetryError(_pool, url, error or ResponseError(cause))
urllib3.exceptions.MaxRetryError: HTTPSConnectionPool(host='api.wandb.ai', port=443): Max retries exceeded with url: /graphql (Caused by ConnectTimeoutError(<urllib3.connection.HTTPSConnection object at 0x7f1bb3705510>, 'Connection to api.wandb.ai timed out. (connect timeout=10)'))

During handling of the above exception, another exception occurred:

Traceback (most recent call last):
  File "/home/mincut/miniconda3/envs/vidgnn/lib/python3.10/site-packages/wandb/apis/normalize.py", line 41, in wrapper
    return func(*args, **kwargs)
  File "/home/mincut/miniconda3/envs/vidgnn/lib/python3.10/site-packages/wandb/sdk/internal/internal_api.py", line 498, in server_settings_introspection
    res = self.gql(query)
  File "/home/mincut/miniconda3/envs/vidgnn/lib/python3.10/site-packages/wandb/sdk/internal/internal_api.py", line 257, in gql
    ret = self._retry_gql(
  File "/home/mincut/miniconda3/envs/vidgnn/lib/python3.10/site-packages/wandb/sdk/lib/retry.py", line 131, in __call__
    result = self._call_fn(*args, **kwargs)
  File "/home/mincut/miniconda3/envs/vidgnn/lib/python3.10/site-packages/wandb/sdk/internal/internal_api.py", line 285, in execute
    return self.client.execute(*args, **kwargs)  # type: ignore
  File "/home/mincut/miniconda3/envs/vidgnn/lib/python3.10/site-packages/wandb/vendor/gql-0.2.0/wandb_gql/client.py", line 52, in execute
    result = self._get_result(document, *args, **kwargs)
  File "/home/mincut/miniconda3/envs/vidgnn/lib/python3.10/site-packages/wandb/vendor/gql-0.2.0/wandb_gql/client.py", line 60, in _get_result
    return self.transport.execute(document, *args, **kwargs)
  File "/home/mincut/miniconda3/envs/vidgnn/lib/python3.10/site-packages/wandb/sdk/lib/gql_request.py", line 55, in execute
    request = self.session.post(self.url, **post_args)
  File "/home/mincut/miniconda3/envs/vidgnn/lib/python3.10/site-packages/requests/sessions.py", line 635, in post
    return self.request("POST", url, data=data, json=json, **kwargs)
  File "/home/mincut/miniconda3/envs/vidgnn/lib/python3.10/site-packages/requests/sessions.py", line 587, in request
    resp = self.send(prep, **send_kwargs)
  File "/home/mincut/miniconda3/envs/vidgnn/lib/python3.10/site-packages/requests/sessions.py", line 701, in send
    r = adapter.send(request, **kwargs)
  File "/home/mincut/miniconda3/envs/vidgnn/lib/python3.10/site-packages/requests/adapters.py", line 553, in send
    raise ConnectTimeout(e, request=request)
requests.exceptions.ConnectTimeout: HTTPSConnectionPool(host='api.wandb.ai', port=443): Max retries exceeded with url: /graphql (Caused by ConnectTimeoutError(<urllib3.connection.HTTPSConnection object at 0x7f1bb3705510>, 'Connection to api.wandb.ai timed out. (connect timeout=10)'))

During handling of the above exception, another exception occurred:

Traceback (most recent call last):
  File "/home/mincut/miniconda3/envs/vidgnn/lib/python3.10/site-packages/wandb/sdk/internal/sender.py", line 977, in send_run
    self._init_run(run, config_value_dict)
  File "/home/mincut/miniconda3/envs/vidgnn/lib/python3.10/site-packages/wandb/sdk/internal/sender.py", line 1015, in _init_run
    server_run, inserted, server_messages = self._api.upsert_run(
  File "/home/mincut/miniconda3/envs/vidgnn/lib/python3.10/site-packages/wandb/apis/normalize.py", line 73, in wrapper
    raise err
  File "/home/mincut/miniconda3/envs/vidgnn/lib/python3.10/site-packages/wandb/apis/normalize.py", line 41, in wrapper
    return func(*args, **kwargs)
  File "/home/mincut/miniconda3/envs/vidgnn/lib/python3.10/site-packages/wandb/sdk/internal/internal_api.py", line 1633, in upsert_run
    self.server_settings_introspection()
  File "/home/mincut/miniconda3/envs/vidgnn/lib/python3.10/site-packages/wandb/apis/normalize.py", line 87, in wrapper
    raise CommError(message, err).with_traceback(sys.exc_info()[2])
  File "/home/mincut/miniconda3/envs/vidgnn/lib/python3.10/site-packages/wandb/apis/normalize.py", line 41, in wrapper
    return func(*args, **kwargs)
  File "/home/mincut/miniconda3/envs/vidgnn/lib/python3.10/site-packages/wandb/sdk/internal/internal_api.py", line 498, in server_settings_introspection
    res = self.gql(query)
  File "/home/mincut/miniconda3/envs/vidgnn/lib/python3.10/site-packages/wandb/sdk/internal/internal_api.py", line 257, in gql
    ret = self._retry_gql(
  File "/home/mincut/miniconda3/envs/vidgnn/lib/python3.10/site-packages/wandb/sdk/lib/retry.py", line 131, in __call__
    result = self._call_fn(*args, **kwargs)
  File "/home/mincut/miniconda3/envs/vidgnn/lib/python3.10/site-packages/wandb/sdk/internal/internal_api.py", line 285, in execute
    return self.client.execute(*args, **kwargs)  # type: ignore
  File "/home/mincut/miniconda3/envs/vidgnn/lib/python3.10/site-packages/wandb/vendor/gql-0.2.0/wandb_gql/client.py", line 52, in execute
    result = self._get_result(document, *args, **kwargs)
  File "/home/mincut/miniconda3/envs/vidgnn/lib/python3.10/site-packages/wandb/vendor/gql-0.2.0/wandb_gql/client.py", line 60, in _get_result
    return self.transport.execute(document, *args, **kwargs)
  File "/home/mincut/miniconda3/envs/vidgnn/lib/python3.10/site-packages/wandb/sdk/lib/gql_request.py", line 55, in execute
    request = self.session.post(self.url, **post_args)
  File "/home/mincut/miniconda3/envs/vidgnn/lib/python3.10/site-packages/requests/sessions.py", line 635, in post
    return self.request("POST", url, data=data, json=json, **kwargs)
  File "/home/mincut/miniconda3/envs/vidgnn/lib/python3.10/site-packages/requests/sessions.py", line 587, in request
    resp = self.send(prep, **send_kwargs)
  File "/home/mincut/miniconda3/envs/vidgnn/lib/python3.10/site-packages/requests/sessions.py", line 701, in send
    r = adapter.send(request, **kwargs)
  File "/home/mincut/miniconda3/envs/vidgnn/lib/python3.10/site-packages/requests/adapters.py", line 553, in send
    raise ConnectTimeout(e, request=request)
wandb.errors.CommError: HTTPSConnectionPool(host='api.wandb.ai', port=443): Max retries exceeded with url: /graphql (Caused by ConnectTimeoutError(<urllib3.connection.HTTPSConnection object at 0x7f1bb3705510>, 'Connection to api.wandb.ai timed out. (connect timeout=10)'))
2023-05-06 15:22:02,040 INFO    SenderThread:3523920 [sender.py:finish():1550] shutting down sender
