2023-05-08 16:16:39,409 INFO    MainThread:1578437 [wandb_setup.py:_flush():76] Configure stats pid to 1578437
2023-05-08 16:16:39,410 INFO    MainThread:1578437 [wandb_setup.py:_flush():76] Loading settings from /home/mincut/.config/wandb/settings
2023-05-08 16:16:39,410 INFO    MainThread:1578437 [wandb_setup.py:_flush():76] Loading settings from /DATATWO/users/mincut/Object-Centric-VideoAnswering/wandb/settings
2023-05-08 16:16:39,410 INFO    MainThread:1578437 [wandb_setup.py:_flush():76] Loading settings from environment variables: {}
2023-05-08 16:16:39,410 INFO    MainThread:1578437 [wandb_setup.py:_flush():76] Applying setup settings: {'_disable_service': False}
2023-05-08 16:16:39,410 INFO    MainThread:1578437 [wandb_setup.py:_flush():76] Inferring run settings from compute environment: {'program_relpath': 'train_decoder.py', 'program': '/DATATWO/users/mincut/Object-Centric-VideoAnswering/train_decoder.py'}
2023-05-08 16:16:39,410 INFO    MainThread:1578437 [wandb_init.py:_log_setup():507] Logging user logs to /DATATWO/users/mincut/Object-Centric-VideoAnswering/wandb/run-20230508_161639-mq1614wo/logs/debug.log
2023-05-08 16:16:39,410 INFO    MainThread:1578437 [wandb_init.py:_log_setup():508] Logging internal logs to /DATATWO/users/mincut/Object-Centric-VideoAnswering/wandb/run-20230508_161639-mq1614wo/logs/debug-internal.log
2023-05-08 16:16:39,410 INFO    MainThread:1578437 [wandb_init.py:init():547] calling init triggers
2023-05-08 16:16:39,410 INFO    MainThread:1578437 [wandb_init.py:init():554] wandb.init called with sweep_config: {}
config: {}
2023-05-08 16:16:39,410 INFO    MainThread:1578437 [wandb_init.py:init():595] starting backend
2023-05-08 16:16:39,410 INFO    MainThread:1578437 [wandb_init.py:init():599] setting up manager
2023-05-08 16:16:39,416 INFO    MainThread:1578437 [backend.py:_multiprocessing_setup():106] multiprocessing start_methods=fork,spawn,forkserver, using: spawn
2023-05-08 16:16:39,422 INFO    MainThread:1578437 [wandb_init.py:init():605] backend started and connected
2023-05-08 16:16:39,425 INFO    MainThread:1578437 [wandb_init.py:init():695] updated telemetry
2023-05-08 16:16:39,428 INFO    MainThread:1578437 [wandb_init.py:init():732] communicating run to backend with 60.0 second timeout
2023-05-08 16:17:07,954 INFO    Thread-1 (wrapped_target):1578437 [retry.py:__call__():172] Retry attempt failed:
Traceback (most recent call last):
  File "/home/mincut/miniconda3/envs/vidgnn/lib/python3.10/site-packages/urllib3/connection.py", line 174, in _new_conn
    conn = connection.create_connection(
  File "/home/mincut/miniconda3/envs/vidgnn/lib/python3.10/site-packages/urllib3/util/connection.py", line 95, in create_connection
    raise err
  File "/home/mincut/miniconda3/envs/vidgnn/lib/python3.10/site-packages/urllib3/util/connection.py", line 85, in create_connection
    sock.connect(sa)
TimeoutError: timed out

During handling of the above exception, another exception occurred:

Traceback (most recent call last):
  File "/home/mincut/miniconda3/envs/vidgnn/lib/python3.10/site-packages/urllib3/connectionpool.py", line 703, in urlopen
    httplib_response = self._make_request(
  File "/home/mincut/miniconda3/envs/vidgnn/lib/python3.10/site-packages/urllib3/connectionpool.py", line 386, in _make_request
    self._validate_conn(conn)
  File "/home/mincut/miniconda3/envs/vidgnn/lib/python3.10/site-packages/urllib3/connectionpool.py", line 1042, in _validate_conn
    conn.connect()
  File "/home/mincut/miniconda3/envs/vidgnn/lib/python3.10/site-packages/urllib3/connection.py", line 358, in connect
    self.sock = conn = self._new_conn()
  File "/home/mincut/miniconda3/envs/vidgnn/lib/python3.10/site-packages/urllib3/connection.py", line 179, in _new_conn
    raise ConnectTimeoutError(
urllib3.exceptions.ConnectTimeoutError: (<urllib3.connection.HTTPSConnection object at 0x7f2f8aaa3a30>, 'Connection to api.wandb.ai timed out. (connect timeout=10)')

During handling of the above exception, another exception occurred:

Traceback (most recent call last):
  File "/home/mincut/miniconda3/envs/vidgnn/lib/python3.10/site-packages/requests/adapters.py", line 489, in send
    resp = conn.urlopen(
  File "/home/mincut/miniconda3/envs/vidgnn/lib/python3.10/site-packages/urllib3/connectionpool.py", line 787, in urlopen
    retries = retries.increment(
  File "/home/mincut/miniconda3/envs/vidgnn/lib/python3.10/site-packages/urllib3/util/retry.py", line 592, in increment
    raise MaxRetryError(_pool, url, error or ResponseError(cause))
urllib3.exceptions.MaxRetryError: HTTPSConnectionPool(host='api.wandb.ai', port=443): Max retries exceeded with url: /graphql (Caused by ConnectTimeoutError(<urllib3.connection.HTTPSConnection object at 0x7f2f8aaa3a30>, 'Connection to api.wandb.ai timed out. (connect timeout=10)'))

During handling of the above exception, another exception occurred:

Traceback (most recent call last):
  File "/home/mincut/miniconda3/envs/vidgnn/lib/python3.10/site-packages/wandb/sdk/lib/retry.py", line 131, in __call__
    result = self._call_fn(*args, **kwargs)
  File "/home/mincut/miniconda3/envs/vidgnn/lib/python3.10/site-packages/wandb/sdk/internal/internal_api.py", line 285, in execute
    return self.client.execute(*args, **kwargs)  # type: ignore
  File "/home/mincut/miniconda3/envs/vidgnn/lib/python3.10/site-packages/wandb/vendor/gql-0.2.0/wandb_gql/client.py", line 52, in execute
    result = self._get_result(document, *args, **kwargs)
  File "/home/mincut/miniconda3/envs/vidgnn/lib/python3.10/site-packages/wandb/vendor/gql-0.2.0/wandb_gql/client.py", line 60, in _get_result
    return self.transport.execute(document, *args, **kwargs)
  File "/home/mincut/miniconda3/envs/vidgnn/lib/python3.10/site-packages/wandb/sdk/lib/gql_request.py", line 55, in execute
    request = self.session.post(self.url, **post_args)
  File "/home/mincut/miniconda3/envs/vidgnn/lib/python3.10/site-packages/requests/sessions.py", line 635, in post
    return self.request("POST", url, data=data, json=json, **kwargs)
  File "/home/mincut/miniconda3/envs/vidgnn/lib/python3.10/site-packages/requests/sessions.py", line 587, in request
    resp = self.send(prep, **send_kwargs)
  File "/home/mincut/miniconda3/envs/vidgnn/lib/python3.10/site-packages/requests/sessions.py", line 701, in send
    r = adapter.send(request, **kwargs)
  File "/home/mincut/miniconda3/envs/vidgnn/lib/python3.10/site-packages/requests/adapters.py", line 553, in send
    raise ConnectTimeout(e, request=request)
requests.exceptions.ConnectTimeout: HTTPSConnectionPool(host='api.wandb.ai', port=443): Max retries exceeded with url: /graphql (Caused by ConnectTimeoutError(<urllib3.connection.HTTPSConnection object at 0x7f2f8aaa3a30>, 'Connection to api.wandb.ai timed out. (connect timeout=10)'))
2023-05-08 16:17:21,348 WARNING MainThread:1578437 [wandb_init.py:init():1167] interrupted
Traceback (most recent call last):
  File "/home/mincut/miniconda3/envs/vidgnn/lib/python3.10/site-packages/wandb/sdk/wandb_init.py", line 1145, in init
    run = wi.init()
  File "/home/mincut/miniconda3/envs/vidgnn/lib/python3.10/site-packages/wandb/sdk/wandb_init.py", line 735, in init
    result = run_init_handle.wait(
  File "/home/mincut/miniconda3/envs/vidgnn/lib/python3.10/site-packages/wandb/sdk/lib/mailbox.py", line 283, in wait
    found, abandoned = self._slot._get_and_clear(timeout=wait_timeout)
  File "/home/mincut/miniconda3/envs/vidgnn/lib/python3.10/site-packages/wandb/sdk/lib/mailbox.py", line 130, in _get_and_clear
    if self._wait(timeout=timeout):
  File "/home/mincut/miniconda3/envs/vidgnn/lib/python3.10/site-packages/wandb/sdk/lib/mailbox.py", line 126, in _wait
    return self._event.wait(timeout=timeout)
  File "/home/mincut/miniconda3/envs/vidgnn/lib/python3.10/threading.py", line 607, in wait
    signaled = self._cond.wait(timeout)
  File "/home/mincut/miniconda3/envs/vidgnn/lib/python3.10/threading.py", line 324, in wait
    gotit = waiter.acquire(True, timeout)
KeyboardInterrupt
