2023-05-08 16:16:39,422 INFO    StreamThr :1578444 [internal.py:wandb_internal():86] W&B internal server running at pid: 1578444, started at: 2023-05-08 16:16:39.421724
2023-05-08 16:16:39,424 DEBUG   HandlerThread:1578444 [handler.py:handle_request():144] handle_request: status
2023-05-08 16:16:39,431 INFO    WriterThread:1578444 [datastore.py:open_for_write():85] open: /DATATWO/users/mincut/Object-Centric-VideoAnswering/wandb/run-20230508_161639-mq1614wo/run-mq1614wo.wandb
2023-05-08 16:16:39,432 DEBUG   SenderThread:1578444 [sender.py:send():375] send: header
2023-05-08 16:16:39,432 DEBUG   SenderThread:1578444 [sender.py:send():375] send: run
2023-05-08 16:16:44,430 DEBUG   HandlerThread:1578444 [handler.py:handle_request():144] handle_request: keepalive
2023-05-08 16:16:49,432 DEBUG   HandlerThread:1578444 [handler.py:handle_request():144] handle_request: keepalive
2023-05-08 16:16:54,434 DEBUG   HandlerThread:1578444 [handler.py:handle_request():144] handle_request: keepalive
2023-05-08 16:16:59,436 DEBUG   HandlerThread:1578444 [handler.py:handle_request():144] handle_request: keepalive
2023-05-08 16:17:04,437 DEBUG   HandlerThread:1578444 [handler.py:handle_request():144] handle_request: keepalive
2023-05-08 16:17:09,439 DEBUG   HandlerThread:1578444 [handler.py:handle_request():144] handle_request: keepalive
2023-05-08 16:17:13,054 INFO    SenderThread:1578444 [retry.py:__call__():172] Retry attempt failed:
Traceback (most recent call last):
  File "/home/mincut/miniconda3/envs/vidgnn/lib/python3.10/site-packages/urllib3/connection.py", line 174, in _new_conn
    conn = connection.create_connection(
  File "/home/mincut/miniconda3/envs/vidgnn/lib/python3.10/site-packages/urllib3/util/connection.py", line 95, in create_connection
    raise err
  File "/home/mincut/miniconda3/envs/vidgnn/lib/python3.10/site-packages/urllib3/util/connection.py", line 85, in create_connection
    sock.connect(sa)
TimeoutError: timed out

During handling of the above exception, another exception occurred:

Traceback (most recent call last):
  File "/home/mincut/miniconda3/envs/vidgnn/lib/python3.10/site-packages/urllib3/connectionpool.py", line 703, in urlopen
    httplib_response = self._make_request(
  File "/home/mincut/miniconda3/envs/vidgnn/lib/python3.10/site-packages/urllib3/connectionpool.py", line 386, in _make_request
    self._validate_conn(conn)
  File "/home/mincut/miniconda3/envs/vidgnn/lib/python3.10/site-packages/urllib3/connectionpool.py", line 1042, in _validate_conn
    conn.connect()
  File "/home/mincut/miniconda3/envs/vidgnn/lib/python3.10/site-packages/urllib3/connection.py", line 358, in connect
    self.sock = conn = self._new_conn()
  File "/home/mincut/miniconda3/envs/vidgnn/lib/python3.10/site-packages/urllib3/connection.py", line 179, in _new_conn
    raise ConnectTimeoutError(
urllib3.exceptions.ConnectTimeoutError: (<urllib3.connection.HTTPSConnection object at 0x7fb126e355a0>, 'Connection to api.wandb.ai timed out. (connect timeout=10)')

During handling of the above exception, another exception occurred:

Traceback (most recent call last):
  File "/home/mincut/miniconda3/envs/vidgnn/lib/python3.10/site-packages/requests/adapters.py", line 489, in send
    resp = conn.urlopen(
  File "/home/mincut/miniconda3/envs/vidgnn/lib/python3.10/site-packages/urllib3/connectionpool.py", line 787, in urlopen
    retries = retries.increment(
  File "/home/mincut/miniconda3/envs/vidgnn/lib/python3.10/site-packages/urllib3/util/retry.py", line 592, in increment
    raise MaxRetryError(_pool, url, error or ResponseError(cause))
urllib3.exceptions.MaxRetryError: HTTPSConnectionPool(host='api.wandb.ai', port=443): Max retries exceeded with url: /graphql (Caused by ConnectTimeoutError(<urllib3.connection.HTTPSConnection object at 0x7fb126e355a0>, 'Connection to api.wandb.ai timed out. (connect timeout=10)'))

During handling of the above exception, another exception occurred:

Traceback (most recent call last):
  File "/home/mincut/miniconda3/envs/vidgnn/lib/python3.10/site-packages/wandb/sdk/lib/retry.py", line 131, in __call__
    result = self._call_fn(*args, **kwargs)
  File "/home/mincut/miniconda3/envs/vidgnn/lib/python3.10/site-packages/wandb/sdk/internal/internal_api.py", line 285, in execute
    return self.client.execute(*args, **kwargs)  # type: ignore
  File "/home/mincut/miniconda3/envs/vidgnn/lib/python3.10/site-packages/wandb/vendor/gql-0.2.0/wandb_gql/client.py", line 52, in execute
    result = self._get_result(document, *args, **kwargs)
  File "/home/mincut/miniconda3/envs/vidgnn/lib/python3.10/site-packages/wandb/vendor/gql-0.2.0/wandb_gql/client.py", line 60, in _get_result
    return self.transport.execute(document, *args, **kwargs)
  File "/home/mincut/miniconda3/envs/vidgnn/lib/python3.10/site-packages/wandb/sdk/lib/gql_request.py", line 55, in execute
    request = self.session.post(self.url, **post_args)
  File "/home/mincut/miniconda3/envs/vidgnn/lib/python3.10/site-packages/requests/sessions.py", line 635, in post
    return self.request("POST", url, data=data, json=json, **kwargs)
  File "/home/mincut/miniconda3/envs/vidgnn/lib/python3.10/site-packages/requests/sessions.py", line 587, in request
    resp = self.send(prep, **send_kwargs)
  File "/home/mincut/miniconda3/envs/vidgnn/lib/python3.10/site-packages/requests/sessions.py", line 701, in send
    r = adapter.send(request, **kwargs)
  File "/home/mincut/miniconda3/envs/vidgnn/lib/python3.10/site-packages/requests/adapters.py", line 553, in send
    raise ConnectTimeout(e, request=request)
requests.exceptions.ConnectTimeout: HTTPSConnectionPool(host='api.wandb.ai', port=443): Max retries exceeded with url: /graphql (Caused by ConnectTimeoutError(<urllib3.connection.HTTPSConnection object at 0x7fb126e355a0>, 'Connection to api.wandb.ai timed out. (connect timeout=10)'))
2023-05-08 16:17:14,441 DEBUG   HandlerThread:1578444 [handler.py:handle_request():144] handle_request: keepalive
2023-05-08 16:17:19,443 DEBUG   HandlerThread:1578444 [handler.py:handle_request():144] handle_request: keepalive
2023-05-08 16:17:21,351 DEBUG   HandlerThread:1578444 [handler.py:handle_request():144] handle_request: shutdown
2023-05-08 16:17:21,351 INFO    HandlerThread:1578444 [handler.py:finish():845] shutting down handler
2023-05-08 16:17:21,438 INFO    WriterThread:1578444 [datastore.py:close():298] close: /DATATWO/users/mincut/Object-Centric-VideoAnswering/wandb/run-20230508_161639-mq1614wo/run-mq1614wo.wandb
